<?xml version="1.0" encoding="utf-8"?>
<!-- This URDF was automatically created by SolidWorks to URDF Exporter! Originally created by Stephen Brawner (brawner@gmail.com) 
     Commit Version: 1.6.0-4-g7f85cfe  Build Version: 1.6.7995.38578
     For more information, please see http://wiki.ros.org/sw_urdf_exporter -->
<robot
  name="arm_robot">
  <link
    name="base_link">
    <inertial>
      <origin
        xyz="4.3658E-17 2.0209E-18 0.026306"
        rpy="0 0 0" />
      <mass
        value="0.134" />
      <inertia
        ixx="5.797E-05"
        ixy="4.039E-24"
        ixz="-4.9245E-21"
        iyy="5.797E-05"
        iyz="2.6382E-22"
        izz="5.422E-05" />
    </inertial>
    <visual>
      <origin
        xyz="0 0 0"
        rpy="0 0 0" />
      <geometry>
        <mesh
          filename="package://arm_robot/meshes/base_link.STL" />
      </geometry>
      <material
        name="">
        <color
          rgba="0.79216 0.81961 0.93333 1" />
      </material>
    </visual>
    <collision>
      <origin
        xyz="0 0 0"
        rpy="0 0 0" />
      <geometry>
        <mesh
          filename="package://arm_robot/meshes/base_link.STL" />
      </geometry>
    </collision>
  </link>
  <link
    name="link_6">
    <inertial>
      <origin
        xyz="1.4316E-17 -0.00035171 0.03104"
        rpy="0 0 0" />
      <mass
        value="0.15154" />
      <inertia
        ixx="6.4227E-05"
        ixy="1.555E-21"
        ixz="8.6655E-22"
        iyy="6.3444E-05"
        iyz="3.8382E-07"
        izz="6.3559E-05" />
    </inertial>
    <visual>
      <origin
        xyz="0 0 0"
        rpy="0 0 0" />
      <geometry>
        <mesh
          filename="package://arm_robot/meshes/link_6.STL" />
      </geometry>
      <material
        name="">
        <color
          rgba="0.79216 0.81961 0.93333 1" />
      </material>
    </visual>
    <collision>
      <origin
        xyz="0 0 0"
        rpy="0 0 0" />
      <geometry>
        <mesh
          filename="package://arm_robot/meshes/link_6.STL" />
      </geometry>
    </collision>
  </link>
  <joint
    name="joint_6"
    type="revolute">
    <origin
      xyz="0 0 0.0563"
      rpy="0 0 0" />
    <parent
      link="base_link" />
    <child
      link="link_6" />
    <axis
      xyz="0 0 1" />
    <limit
      lower="-3"
      upper="3"
      effort="1"
      velocity="1" />
    <dynamics
      damping="1"
      friction="1" />
    <safety_controller
      soft_upper_limit="3"
      soft_lower_limit="-3"
      k_position="1"
      k_velocity="1" />
  </joint>
  <link
    name="link_5">
    <inertial>
      <origin
        xyz="0.23253 5.5511E-17 -0.023931"
        rpy="0 0 0" />
      <mass
        value="0.21404" />
      <inertia
        ixx="6.3317E-05"
        ixy="-1.8384E-20"
        ixz="2.4161E-10"
        iyy="0.00032731"
        iyz="-2.1399E-20"
        izz="0.00032357" />
    </inertial>
    <visual>
      <origin
        xyz="0 0 0"
        rpy="0 0 0" />
      <geometry>
        <mesh
          filename="package://arm_robot/meshes/link_5.STL" />
      </geometry>
      <material
        name="">
        <color
          rgba="1 1 1 1" />
      </material>
    </visual>
    <collision>
      <origin
        xyz="0 0 0"
        rpy="0 0 0" />
      <geometry>
        <mesh
          filename="package://arm_robot/meshes/link_5.STL" />
      </geometry>
    </collision>
  </link>
  <joint
    name="joint_5"
    type="revolute">
    <origin
      xyz="0 -0.033175 0.033"
      rpy="-1.5708 0 -3.1416" />
    <parent
      link="link_6" />
    <child
      link="link_5" />
    <axis
      xyz="0 0 1" />
    <limit
      lower="-3"
      upper="3"
      effort="1"
      velocity="1" />
    <dynamics
      damping="1"
      friction="1" />
    <safety_controller
      soft_upper_limit="3"
      soft_lower_limit="-3"
      k_position="1"
      k_velocity="1" />
  </joint>
  <link
    name="link_4">
    <inertial>
      <origin
        xyz="0.012508 -0.050154 -0.031376"
        rpy="0 0 0" />
      <mass
        value="0.0001863" />
      <inertia
        ixx="8.9072E-08"
        ixy="5.9674E-09"
        ixz="-6.2698E-13"
        iyy="6.1154E-08"
        iyz="1.029E-13"
        izz="8.6192E-08" />
    </inertial>
    <visual>
      <origin
        xyz="0 0 0"
        rpy="0 0 0" />
      <geometry>
        <mesh
          filename="package://arm_robot/meshes/link_4.STL" />
      </geometry>
      <material
        name="">
        <color
          rgba="0.79216 0.81961 0.93333 1" />
      </material>
    </visual>
    <collision>
      <origin
        xyz="0 0 0"
        rpy="0 0 0" />
      <geometry>
        <mesh
          filename="package://arm_robot/meshes/link_4.STL" />
      </geometry>
    </collision>
  </link>
  <joint
    name="joint_4"
    type="revolute">
    <origin
      xyz="0.286 0 0.0143"
      rpy="0 0 0" />
    <parent
      link="link_5" />
    <child
      link="link_4" />
    <axis
      xyz="0 0 -1" />
    <limit
      lower="-3"
      upper="3"
      effort="1"
      velocity="1" />
    <dynamics
      damping="1"
      friction="1" />
    <safety_controller
      soft_upper_limit="3"
      soft_lower_limit="-3"
      k_position="1"
      k_velocity="1" />
  </joint>
  <link
    name="link_3">
    <inertial>
      <origin
        xyz="-7.8063E-17 -0.0031529 0.097839"
        rpy="0 0 0" />
      <mass
        value="0.09211" />
      <inertia
        ixx="0.00020224"
        ixy="-7.9455E-16"
        ixz="1.0827E-19"
        iyy="0.00020593"
        iyz="1.2343E-09"
        izz="1.0799E-05" />
    </inertial>
    <visual>
      <origin
        xyz="0 0 0"
        rpy="0 0 0" />
      <geometry>
        <mesh
          filename="package://arm_robot/meshes/link_3.STL" />
      </geometry>
      <material
        name="">
        <color
          rgba="0.79216 0.81961 0.93333 1" />
      </material>
    </visual>
    <collision>
      <origin
        xyz="0 0 0"
        rpy="0 0 0" />
      <geometry>
        <mesh
          filename="package://arm_robot/meshes/link_3.STL" />
      </geometry>
    </collision>
  </link>
  <joint
    name="joint_3"
    type="revolute">
    <origin
      xyz="-0.0255 -0.057 -0.0385"
      rpy="3.1416 1.5708 0" />
    <parent
      link="link_4" />
    <child
      link="link_3" />
    <axis
      xyz="0 0 -1" />
    <limit
      lower="-3"
      upper="3"
      effort="1"
      velocity="1" />
    <dynamics
      damping="1"
      friction="1" />
    <safety_controller
      soft_upper_limit="3"
      soft_lower_limit="-3"
      k_position="1"
      k_velocity="1" />
  </joint>
  <link
    name="link_2">
    <inertial>
      <origin
        xyz="0.058734 -5.7246E-17 -0.024752"
        rpy="0 0 0" />
      <mass
        value="0.00014694" />
      <inertia
        ixx="5.8114E-08"
        ixy="3.9873E-24"
        ixz="-6.9618E-13"
        iyy="4.9317E-08"
        iyz="1.967E-24"
        izz="5.2432E-08" />
    </inertial>
    <visual>
      <origin
        xyz="0 0 0"
        rpy="0 0 0" />
      <geometry>
        <mesh
          filename="package://arm_robot/meshes/link_2.STL" />
      </geometry>
      <material
        name="">
        <color
          rgba="1 1 1 1" />
      </material>
    </visual>
    <collision>
      <origin
        xyz="0 0 0"
        rpy="0 0 0" />
      <geometry>
        <mesh
          filename="package://arm_robot/meshes/link_2.STL" />
      </geometry>
    </collision>
  </link>
  <joint
    name="joint_2"
    type="revolute">
    <origin
      xyz="0 0.026 0.2185"
      rpy="-1.5708 -1.5708 0" />
    <parent
      link="link_3" />
    <child
      link="link_2" />
    <axis
      xyz="0 0 -1" />
    <limit
      lower="-3"
      upper="3"
      effort="1"
      velocity="1" />
    <dynamics
      damping="1"
      friction="1" />
    <safety_controller
      soft_upper_limit="3"
      soft_lower_limit="-3"
      k_position="1"
      k_velocity="1" />
  </joint>
  <link
    name="link_1">
    <inertial>
      <origin
        xyz="4.8572E-17 2.7756E-17 0.005"
        rpy="0 0 0" />
      <mass
        value="0.0057256" />
      <inertia
        ixx="3.0858E-07"
        ixy="4.4116E-24"
        ixz="3.2362E-22"
        iyy="3.0858E-07"
        iyz="-4.3305E-24"
        izz="5.2174E-07" />
    </inertial>
    <visual>
      <origin
        xyz="0 0 0"
        rpy="0 0 0" />
      <geometry>
        <mesh
          filename="package://arm_robot/meshes/link_1.STL" />
      </geometry>
      <material
        name="">
        <color
          rgba="1 1 1 1" />
      </material>
    </visual>
    <collision>
      <origin
        xyz="0 0 0"
        rpy="0 0 0" />
      <geometry>
        <mesh
          filename="package://arm_robot/meshes/link_1.STL" />
      </geometry>
    </collision>
  </link>
  <joint
    name="joint_1"
    type="revolute">
    <origin
      xyz="0.089 0 -0.026"
      rpy="1.5708 0 1.5708" />
    <parent
      link="link_2" />
    <child
      link="link_1" />
    <axis
      xyz="0 0 -1" />
    <limit
      lower="-3"
      upper="3"
      effort="1"
      velocity="1" />
    <dynamics
      damping="1"
      friction="1" />
    <safety_controller
      soft_upper_limit="3"
      soft_lower_limit="-3"
      k_position="1"
      k_velocity="1" />
  </joint>
</robot>